Workbook
Name CmpChild: Inputs!$D$11
Name Coverage: Inputs!$D$8
Name Ctry_Ccy: Lists!$H$2:$H$12
Name Ctry_LInf: Lists!$I$2:$I$12
Name Ctry_Name: Lists!$G$2:$G$12
Name DB_Avail: 'Cost Database'!$G$5:$G$488
Name DB_Dur: 'Cost Database'!$F$5:$F$488
Name DB_EduCcy: 'Cost Database'!$E$5:$E$488
Name DB_EstAdm: 'Cost Database'!$R$5:$R$488
Name DB_EstBase: 'Cost Database'!$O$5:$O$488
Name DB_EstCcy: 'Cost Database'!$N$5:$N$488
Name DB_EstOther: 'Cost Database'!$Q$5:$Q$488
Name DB_EstStatus: 'Cost Database'!$M$5:$M$488
Name DB_EstTuition: 'Cost Database'!$P$5:$P$488
Name DB_Key: 'Cost Database'!$A$5:$A$488
Name DB_PreAdm: 'Cost Database'!$X$5:$X$488
Name DB_PreBase: 'Cost Database'!$U$5:$U$488
Name DB_PreCcy: 'Cost Database'!$T$5:$T$488
Name DB_PreOther: 'Cost Database'!$W$5:$W$488
Name DB_PreStatus: 'Cost Database'!$S$5:$S$488
Name DB_PreTuition: 'Cost Database'!$V$5:$V$488
Name DB_PreYears: 'Cost Database'!$H$5:$H$488
Name DB_RecCcy: 'Cost Database'!$L$5:$L$488
Name DB_TInf: 'Cost Database'!$J$5:$J$488
Name DomKey: Lists!$E$2:$E$50
Name FxCodes: 'Assumptions and Currency'!$A$8:$A$17
Name FxUsed: 'Assumptions and Currency'!$D$8:$D$17
Name Liv_accommodation_Amt: 'Living Costs'!$B$5:$B$26
Name Liv_accommodation_Base: 'Living Costs'!$D$5:$D$26
Name Liv_accommodation_Ccy: 'Living Costs'!$C$5:$C$26
Name Liv_accommodation_Status: 'Living Costs'!$E$5:$E$26
Name Liv_books_Amt: 'Living Costs'!$R$5:$R$26
Name Liv_books_Base: 'Living Costs'!$T$5:$T$26
Name Liv_books_Ccy: 'Living Costs'!$S$5:$S$26
Name Liv_books_Status: 'Living Costs'!$U$5:$U$26
Name Liv_food_Amt: 'Living Costs'!$F$5:$F$26
Name Liv_food_Base: 'Living Costs'!$H$5:$H$26
Name Liv_food_Ccy: 'Living Costs'!$G$5:$G$26
Name Liv_food_Status: 'Living Costs'!$I$5:$I$26
Name Liv_healthInsurance_Amt: 'Living Costs'!$N$5:$N$26
Name Liv_healthInsurance_Base: 'Living Costs'!$P$5:$P$26
Name Liv_healthInsurance_Ccy: 'Living Costs'!$O$5:$O$26
Name Liv_healthInsurance_Status: 'Living Costs'!$Q$5:$Q$26
Name Liv_transport_Amt: 'Living Costs'!$J$5:$J$26
Name Liv_transport_Base: 'Living Costs'!$L$5:$L$26
Name Liv_transport_Ccy: 'Living Costs'!$K$5:$K$26
Name Liv_transport_Status: 'Living Costs'!$M$5:$M$26
Name LivKey: 'Living Costs'!$A$5:$A$26
Name Nationality: Inputs!$C$6
Name NumChildren: Inputs!$D$4
Name PlanYear: 'Assumptions and Currency'!$B$3
Name RecAdm: 'Fee Records'!$H$5:$H$438
Name RecKey: 'Fee Records'!$A$5:$A$438
Name RecOther: 'Fee Records'!$G$5:$G$438
Name RecTuition: 'Fee Records'!$F$5:$F$438
Name RecYear: 'Fee Records'!$D$5:$D$438
Name RepCcy: Inputs!$D$7
Name Residence: Inputs!$C$5
Name ResNoVisa: Lists!$K$2:$K$3
Name Ret_Ccy: 'Assumptions and Currency'!$A$22:$A$31

Sheet Start Here
B2: Children's Future Education Fund Calculator
B3: Sindhi Connect - sindhiconnect.org
B5: How to use
B6: 1. Go to the Inputs sheet and fill in the yellow cells: your family details and, for each child, age, education country and qualification.
B7: 2. Open the Dashboard: total education fund required, required yearly savings, amount needed now, each child, cost breakdown and the year-by-year plan.
B8: 3. Compare Countries shows the same course in all 11 study countries.
B9: 4. Each child's sheet shows every cost line with its status (Published figure / Estimated — please review / Not needed / Your figure) and the full calculation.
B10: 5. To use your own figures, type them in the 'Your own cost figures' rows on the Inputs sheet (today's prices, education country's currency).
B12: Important
B13: Educational planning tool only. Fees, living costs, inflation, exchange rates and investment returns may differ from these figures. Figures marked 'Estimated — please review' are planning estimates, not official fees. Investment returns are assumptions, not guarantees. Always confirm fees with the university.
B14: Results are in US dollars unless you choose another currency. The workbook uses formulas only (no macros). It follows the same method as the calculator on the website; see the Sources and Method sheet.
B15: Fees checked on 2026-10-15. Exchange rates of 2026-10-01 (you can enter your own on the Assumptions and Currency sheet).

Sheet Inputs
B1: Children's Future Education Fund - your inputs
B2: Fill in the yellow cells. Leave a cell blank to use the researched figure or default. Results are on the Dashboard.
B3: Family | D3: Value used
B4: Number of children (1-4) | C4: 1 | D4: =MIN(4,MAX(1,ROUND(N(C4),0))) -> 1 | G4: Children beyond this number are ignored.
B5: Country where your family lives | C5: Pakistan | G5: Used for first-travel estimates.
B6: Children's nationality | C6: Pakistan | G6: Decides local or international fees and visa costs.
B7: Show results in (currency) | C7: USD | D7: =IF(C7="Automatic",IFERROR(INDEX(Ctry_Ccy,MATCH(C17,Ctry_Name,0)),"USD"),IF(C7="","USD",C7)) -> USD | G7: 'Automatic' uses Child 1's study country currency.
B8: Covered by scholarship / part-time work | C8: 0 | D8: =MIN(1,MAX(0,N(C8))) -> 0 | G8: Reduces tuition, university fees and living costs. Visa and travel are not reduced.
B9: Investment return per year (blank = default for the currency) | D9: =IF(ISNUMBER(C9),C9,IFERROR(INDEX(Ret_Rate,MATCH(D7,Ret_Ccy,0)),0.05)) -> 0.06 | G9: An assumption, not a guarantee.
B10: Yearly increase in your savings | C10: 0 | D10: =N(C10) -> 0 | G10: 0% = the same amount every year.
B11: Compare countries for child number | C11: 1 | D11: =MIN(D4,MAX(1,ROUND(N(C11),0))) -> 1 | G11: Used on the Compare Countries sheet.
B13: Children | C13: Child 1 | D13: Child 2 | E13: Child 3 | F13: Child 4
B14: Name (optional)
B15: Current age (0-18)
B16: Current school class (0-13, for your reference)
B17: Education country
B18: Qualification
B19: College-entry age (usually 18) | C19: 18 | D19: 18 | E19: 18 | F19: 18
B20: Your own fee increase per year (blank = researched default)
B21: Your own living-cost increase per year (blank = default)
B22: Your own cost figures (optional) - per year unless one-time, today's prices, in the education country's currency
B23: Tuition
B24: Accommodation
B25: Food
B26: Local transport
B27: Health insurance
B28: Books and supplies
B29: Other university and course fees
B30: Admission and one-time fees (one-time)
B31: Visa and application (one-time)
... B36: Researched figures and their sources are on each child's sheet (Child 1 to Child 4). Figures marked 'Estimated — please review' are planning estimates, not official fees.

Sheet Dashboard
B1: Children's Future Education Fund - dashboard
B2: ="All amounts in "&RepCcy&", at future prices. Planning estimates only - not financial advice." -> All amounts in USD, at future prices. Planning estimates only - not financial advice.
B4: Total education fund required | C4: ='Child 1'!$Z$56+'Child 2'!$Z$56+'Child 3'!$Z$56+'Child 4'!$Z$56 -> 0 | D4: =IF(C4=0,"Enter your family and children's details on the Inputs sheet to see the figures.","") -> Enter your family and children's details on the Inputs sheet to see the figures.
B5: Required yearly savings (this year) | C5: ='Child 1'!$N$65+'Child 2'!$N$65+'Child 3'!$N$65+'Child 4'!$N$65 -> 0
B6: Amount needed now | C6: ='Child 1'!$B$126+'Child 2'!$B$126+'Child 3'!$B$126+'Child 4'!$B$126 -> 0 | D6: =IF(C6>0.5,"Plus about "&TEXT(C6,"#,##0")&" "&RepCcy&" needed now, because a course starts before any yearly saving can be made.","")
B7: Covered by scholarship / part-time work | C7: ='Child 1'!$B$59+'Child 2'!$B$59+'Child 3'!$B$59+'Child 4'!$B$59 -> 0
B8: Plan length (years) | C8: =MAX('Child 1'!$B$20,'Child 2'!$B$20,'Child 3'!$B$20,'Child 4'!$B$20) -> 0
B10: Each child
B11: Child | C11: Education country | D11: Qualification | E11: Course length (years) | F11: Education starts in | G11: ="Total ("&RepCcy&")" -> Total (USD) | H11: Message
B12: =IF(1<=NumChildren,IF(Inputs!$C$14<>"",Inputs!$C$14,"Child 1"),"") -> Child 1 | C12: =IF(1<=NumChildren,'Child 1'!$B$5,"") | D12: =IF(1<=NumChildren,'Child 1'!$B$6,"") | E12: =IF(AND(1<=NumChildren,'Child 1'!$B$22=1),'Child 1'!$B$13,"") | F12: =IF(AND(1<=NumChildren,'Child 1'!$B$22=1),IF('Child 1'!$B$18=0,"This year",'Child 1'!$B$18&" years")&" ("&(PlanYear+'Child 1'!$B$18)&"/"&RIGHT(PlanYear+'Child 1'!$B$18+1,2)&")","") | G12: =IF(1<=NumChildren,'Child 1'!$Z$56,"") -> 0 | H12: =IF(1<=NumChildren,'Child 1'!$B$23,"") -> Enter this child's details on the Inputs sheet.
B13: =IF(2<=NumChildren,IF(Inputs!$D$14<>"",Inputs!$D$14,"Child 2"),"") | C13: =IF(2<=NumChildren,'Child 2'!$B$5,"") | D13: =IF(2<=NumChildren,'Child 2'!$B$6,"") | E13: =IF(AND(2<=NumChildren,'Child 2'!$B$22=1),'Child 2'!$B$13,"") | F13: =IF(AND(2<=NumChildren,'Child 2'!$B$22=1),IF('Child 2'!$B$18=0,"This year",'Child 2'!$B$18&" years")&" ("&(PlanYear+'Child 2'!$B$18)&"/"&RIGHT(PlanYear+'Child 2'!$B$18+1,2)&")","") | G13: =IF(2<=NumChildren,'Child 2'!$Z$56,"") | H13: =IF(2<=NumChildren,'Child 2'!$B$23,"")
B14: =IF(3<=NumChildren,IF(Inputs!$E$14<>"",Inputs!$E$14,"Child 3"),"") | C14: =IF(3<=NumChildren,'Child 3'!$B$5,"") | D14: =IF(3<=NumChildren,'Child 3'!$B$6,"") | E14: =IF(AND(3<=NumChildren,'Child 3'!$B$22=1),'Child 3'!$B$13,"") | F14: =IF(AND(3<=NumChildren,'Child 3'!$B$22=1),IF('Child 3'!$B$18=0,"This year",'Child 3'!$B$18&" years")&" ("&(PlanYear+'Child 3'!$B$18)&"/"&RIGHT(PlanYear+'Child 3'!$B$18+1,2)&")","") | G14: =IF(3<=NumChildren,'Child 3'!$Z$56,"") | H14: =IF(3<=NumChildren,'Child 3'!$B$23,"")
B15: =IF(4<=NumChildren,IF(Inputs!$F$14<>"",Inputs!$F$14,"Child 4"),"") | C15: =IF(4<=NumChildren,'Child 4'!$B$5,"") | D15: =IF(4<=NumChildren,'Child 4'!$B$6,"") | E15: =IF(AND(4<=NumChildren,'Child 4'!$B$22=1),'Child 4'!$B$13,"") | F15: =IF(AND(4<=NumChildren,'Child 4'!$B$22=1),IF('Child 4'!$B$18=0,"This year",'Child 4'!$B$18&" years")&" ("&(PlanYear+'Child 4'!$B$18)&"/"&RIGHT(PlanYear+'Child 4'!$B$18+1,2)&")","") | G15: =IF(4<=NumChildren,'Child 4'!$Z$56,"") | H15: =IF(4<=NumChildren,'Child 4'!$B$23,"")
B16: All children | G16: =C4 -> 0
B18: Where the money goes
B19: Cost type | C19: ="Amount ("&RepCcy&")" -> Amount (USD) | D19: Share
B20: Tuition | C20: ='Child 1'!$P$56+'Child 2'!$P$56+'Child 3'!$P$56+'Child 4'!$P$56 -> 0 | D20: =IF($C$4>0,C20/$C$4,0) -> 0
B21: Accommodation | C21: ='Child 1'!$Q$56+'Child 2'!$Q$56+'Child 3'!$Q$56+'Child 4'!$Q$56 -> 0 | D21: =IF($C$4>0,C21/$C$4,0) -> 0
B22: Food | C22: ='Child 1'!$R$56+'Child 2'!$R$56+'Child 3'!$R$56+'Child 4'!$R$56 -> 0 | D22: =IF($C$4>0,C22/$C$4,0) -> 0
B23: Local transport | C23: ='Child 1'!$S$56+'Child 2'!$S$56+'Child 3'!$S$56+'Child 4'!$S$56 -> 0 | D23: =IF($C$4>0,C23/$C$4,0) -> 0
B24: Health insurance | C24: ='Child 1'!$T$56+'Child 2'!$T$56+'Child 3'!$T$56+'Child 4'!$T$56 -> 0 | D24: =IF($C$4>0,C24/$C$4,0) -> 0
B25: Books and supplies | C25: ='Child 1'!$U$56+'Child 2'!$U$56+'Child 3'!$U$56+'Child 4'!$U$56 -> 0 | D25: =IF($C$4>0,C25/$C$4,0) -> 0
B26: Other university and course fees | C26: ='Child 1'!$V$56+'Child 1'!$W$56+'Child 2'!$V$56+'Child 2'!$W$56+'Child 3'!$V$56+'Child 3'!$W$56+'Child 4'!$V$56+'Child 4'!$W$56 -> 0 | D26: =IF($C$4>0,C26/$C$4,0) -> 0
B27: Visa, application, travel and relocation | C27: ='Child 1'!$X$56+'Child 1'!$Y$56+'Child 2'!$X$56+'Child 2'!$Y$56+'Child 3'!$X$56+'Child 3'!$Y$56+'Child 4'!$X$56+'Child 4'!$Y$56 -> 0 | D27: =IF($C$4>0,C27/$C$4,0) -> 0
B28: Total | C28: =SUM(C20:C27) -> 0
B30: Year-by-year plan - how the education fund builds up and is spent
B31: Year | C31: Studying | D31: Opening fund | E31: Family savings added | F31: Investment growth | G31: Education expenses | H31: Closing fund | T31: Year | U31: =IF(Inputs!$C$14<>"",Inputs!$C$14,"Child 1") -> Child 1 | V31: =IF(Inputs!$D$14<>"",Inputs!$D$14,"Child 2") -> Child 2 | W31: =IF(Inputs!$E$14<>"",Inputs!$E$14,"Child 3") -> Child 3 | X31: =IF(Inputs!$F$14<>"",Inputs!$F$14,"Child 4") -> Child 4 | Y31: Family savings
B32: =IF(1<=$C$8,(PlanYear+0)&"/"&RIGHT(PlanYear+1,2),"") | C32: =IF(1<=$C$8,MID(IF('Child 1'!$Q$65=1,", "&IF(Inputs!$C$14<>"",Inputs!$C$14,"Child 1"),"")&IF('Child 2'!$Q$65=1,", "&IF(Inputs!$D$14<>"",Inputs!$D$14,"Child 2"),"")&IF('Child 3'!$Q$65=1,", "&IF(Inputs!$E$14<>"",Inputs!$E$14,"Child 3"),"")&IF('Child 4'!$Q$65=1,", "&IF(Inputs!$F$14<>"",Inputs!$F$14,"Child 4"),""),3,200),"") | D32: =IF(1<=$C$8,ROUND('Child 1'!$M$65+'Child 2'!$M$65+'Child 3'!$M$65+'Child 4'!$M$65,2),"") | E32: =IF(1<=$C$8,ROUND('Child 1'!$N$65+'Child 2'!$N$65+'Child 3'!$N$65+'Child 4'!$N$65,2),"") | F32: =IF(1<=$C$8,ROUND('Child 1'!$O$65+'Child 2'!$O$65+'Child 3'!$O$65+'Child 4'!$O$65,2),"") | G32: =IF(1<=$C$8,ROUND('Child 1'!$D$65+'Child 2'!$D$65+'Child 3'!$D$65+'Child 4'!$D$65,2),"") | H32: =IF(1<=$C$8,ROUND('Child 1'!$P$65+'Child 2'!$P$65+'Child 3'!$P$65+'Child 4'!$P$65,2),"") | T32: =IF(1<=$C$8,B32,"") | U32: =IF(1<=$C$8,'Child 1'!$D$65,NA()) -> #N/A | V32: =IF(1<=$C$8,'Child 2'!$D$65,NA()) -> #N/A | W32: =IF(1<=$C$8,'Child 3'!$D$65,NA()) -> #N/A | X32: =IF(1<=$C$8,'Child 4'!$D$65,NA()) -> #N/A | Y32: =IF(1<=$C$8,E32,NA()) -> #N/A
B33: =IF(2<=$C$8,(PlanYear+1)&"/"&RIGHT(PlanYear+2,2),"") | C33: =IF(2<=$C$8,MID(IF('Child 1'!$Q$66=1,", "&IF(Inputs!$C$14<>"",Inputs!$C$14,"Child 1"),"")&IF('Child 2'!$Q$66=1,", "&IF(Inputs!$D$14<>"",Inputs!$D$14,"Child 2"),"")&IF('Child 3'!$Q$66=1,", "&IF(Inputs!$E$14<>"",Inputs!$E$14,"Child 3"),"")&IF('Child 4'!$Q$66=1,", "&IF(Inputs!$F$14<>"",Inputs!$F$14,"Child 4"),""),3,200),"") | D33: =IF(2<=$C$8,ROUND('Child 1'!$M$66+'Child 2'!$M$66+'Child 3'!$M$66+'Child 4'!$M$66,2),"") | E33: =IF(2<=$C$8,ROUND('Child 1'!$N$66+'Child 2'!$N$66+'Child 3'!$N$66+'Child 4'!$N$66,2),"") | F33: =IF(2<=$C$8,ROUND('Child 1'!$O$66+'Child 2'!$O$66+'Child 3'!$O$66+'Child 4'!$O$66,2),"") | G33: =IF(2<=$C$8,ROUND('Child 1'!$D$66+'Child 2'!$D$66+'Child 3'!$D$66+'Child 4'!$D$66,2),"") | H33: =IF(2<=$C$8,ROUND('Child 1'!$P$66+'Child 2'!$P$66+'Child 3'!$P$66+'Child 4'!$P$66,2),"") | T33: =IF(2<=$C$8,B33,"") | U33: =IF(2<=$C$8,'Child 1'!$D$66,NA()) -> #N/A | V33: =IF(2<=$C$8,'Child 2'!$D$66,NA()) -> #N/A | W33: =IF(2<=$C$8,'Child 3'!$D$66,NA()) -> #N/A | X33: =IF(2<=$C$8,'Child 4'!$D$66,NA()) -> #N/A | Y33: =IF(2<=$C$8,E33,NA()) -> #N/A
B34: =IF(3<=$C$8,(PlanYear+2)&"/"&RIGHT(PlanYear+3,2),"") | C34: =IF(3<=$C$8,MID(IF('Child 1'!$Q$67=1,", "&IF(Inputs!$C$14<>"",Inputs!$C$14,"Child 1"),"")&IF('Child 2'!$Q$67=1,", "&IF(Inputs!$D$14<>"",Inputs!$D$14,"Child 2"),"")&IF('Child 3'!$Q$67=1,", "&IF(Inputs!$E$14<>"",Inputs!$E$14,"Child 3"),"")&IF('Child 4'!$Q$67=1,", "&IF(Inputs!$F$14<>"",Inputs!$F$14,"Child 4"),""),3,200),"") | D34: =IF(3<=$C$8,ROUND('Child 1'!$M$67+'Child 2'!$M$67+'Child 3'!$M$67+'Child 4'!$M$67,2),"") | E34: =IF(3<=$C$8,ROUND('Child 1'!$N$67+'Child 2'!$N$67+'Child 3'!$N$67+'Child 4'!$N$67,2),"") | F34: =IF(3<=$C$8,ROUND('Child 1'!$O$67+'Child 2'!$O$67+'Child 3'!$O$67+'Child 4'!$O$67,2),"") | G34: =IF(3<=$C$8,ROUND('Child 1'!$D$67+'Child 2'!$D$67+'Child 3'!$D$67+'Child 4'!$D$67,2),"") | H34: =IF(3<=$C$8,ROUND('Child 1'!$P$67+'Child 2'!$P$67+'Child 3'!$P$67+'Child 4'!$P$67,2),"") | T34: =IF(3<=$C$8,B34,"") | U34: =IF(3<=$C$8,'Child 1'!$D$67,NA()) -> #N/A | V34: =IF(3<=$C$8,'Child 2'!$D$67,NA()) -> #N/A | W34: =IF(3<=$C$8,'Child 3'!$D$67,NA()) -> #N/A | X34: =IF(3<=$C$8,'Child 4'!$D$67,NA()) -> #N/A | Y34: =IF(3<=$C$8,E34,NA()) -> #N/A
B35: =IF(4<=$C$8,(PlanYear+3)&"/"&RIGHT(PlanYear+4,2),"") | C35: =IF(4<=$C$8,MID(IF('Child 1'!$Q$68=1,", "&IF(Inputs!$C$14<>"",Inputs!$C$14,"Child 1"),"")&IF('Child 2'!$Q$68=1,", "&IF(Inputs!$D$14<>"",Inputs!$D$14,"Child 2"),"")&IF('Child 3'!$Q$68=1,", "&IF(Inputs!$E$14<>"",Inputs!$E$14,"Child 3"),"")&IF('Child 4'!$Q$68=1,", "&IF(Inputs!$F$14<>"",Inputs!$F$14,"Child 4"),""),3,200),"") | D35: =IF(4<=$C$8,ROUND('Child 1'!$M$68+'Child 2'!$M$68+'Child 3'!$M$68+'Child 4'!$M$68,2),"") | E35: =IF(4<=$C$8,ROUND('Child 1'!$N$68+'Child 2'!$N$68+'Child 3'!$N$68+'Child 4'!$N$68,2),"") | F35: =IF(4<=$C$8,ROUND('Child 1'!$O$68+'Child 2'!$O$68+'Child 3'!$O$68+'Child 4'!$O$68,2),"") | G35: =IF(4<=$C$8,ROUND('Child 1'!$D$68+'Child 2'!$D$68+'Child 3'!$D$68+'Child 4'!$D$68,2),"") | H35: =IF(4<=$C$8,ROUND('Child 1'!$P$68+'Child 2'!$P$68+'Child 3'!$P$68+'Child 4'!$P$68,2),"") | T35: =IF(4<=$C$8,B35,"") | U35: =IF(4<=$C$8,'Child 1'!$D$68,NA()) -> #N/A | V35: =IF(4<=$C$8,'Child 2'!$D$68,NA()) -> #N/A | W35: =IF(4<=$C$8,'Child 3'!$D$68,NA()) -> #N/A | X35: =IF(4<=$C$8,'Child 4'!$D$68,NA()) -> #N/A | Y35: =IF(4<=$C$8,E35,NA()) -> #N/A
B36: =IF(5<=$C$8,(PlanYear+4)&"/"&RIGHT(PlanYear+5,2),"") | C36: =IF(5<=$C$8,MID(IF('Child 1'!$Q$69=1,", "&IF(Inputs!$C$14<>"",Inputs!$C$14,"Child 1"),"")&IF('Child 2'!$Q$69=1,", "&IF(Inputs!$D$14<>"",Inputs!$D$14,"Child 2"),"")&IF('Child 3'!$Q$69=1,", "&IF(Inputs!$E$14<>"",Inputs!$E$14,"Child 3"),"")&IF('Child 4'!$Q$69=1,", "&IF(Inputs!$F$14<>"",Inputs!$F$14,"Child 4"),""),3,200),"") | D36: =IF(5<=$C$8,ROUND('Child 1'!$M$69+'Child 2'!$M$69+'Child 3'!$M$69+'Child 4'!$M$69,2),"") | E36: =IF(5<=$C$8,ROUND('Child 1'!$N$69+'Child 2'!$N$69+'Child 3'!$N$69+'Child 4'!$N$69,2),"") | F36: =IF(5<=$C$8,ROUND('Child 1'!$O$69+'Child 2'!$O$69+'Child 3'!$O$69+'Child 4'!$O$69,2),"") | G36: =IF(5<=$C$8,ROUND('Child 1'!$D$69+'Child 2'!$D$69+'Child 3'!$D$69+'Child 4'!$D$69,2),"") | H36: =IF(5<=$C$8,ROUND('Child 1'!$P$69+'Child 2'!$P$69+'Child 3'!$P$69+'Child 4'!$P$69,2),"") | T36: =IF(5<=$C$8,B36,"") | U36: =IF(5<=$C$8,'Child 1'!$D$69,NA()) -> #N/A | V36: =IF(5<=$C$8,'Child 2'!$D$69,NA()) -> #N/A | W36: =IF(5<=$C$8,'Child 3'!$D$69,NA()) -> #N/A | X36: =IF(5<=$C$8,'Child 4'!$D$69,NA()) -> #N/A | Y36: =IF(5<=$C$8,E36,NA()) -> #N/A
B37: =IF(6<=$C$8,(PlanYear+5)&"/"&RIGHT(PlanYear+6,2),"") | C37: =IF(6<=$C$8,MID(IF('Child 1'!$Q$70=1,", "&IF(Inputs!$C$14<>"",Inputs!$C$14,"Child 1"),"")&IF('Child 2'!$Q$70=1,", "&IF(Inputs!$D$14<>"",Inputs!$D$14,"Child 2"),"")&IF('Child 3'!$Q$70=1,", "&IF(Inputs!$E$14<>"",Inputs!$E$14,"Child 3"),"")&IF('Child 4'!$Q$70=1,", "&IF(Inputs!$F$14<>"",Inputs!$F$14,"Child 4"),""),3,200),"") | D37: =IF(6<=$C$8,ROUND('Child 1'!$M$70+'Child 2'!$M$70+'Child 3'!$M$70+'Child 4'!$M$70,2),"") | E37: =IF(6<=$C$8,ROUND('Child 1'!$N$70+'Child 2'!$N$70+'Child 3'!$N$70+'Child 4'!$N$70,2),"") | F37: =IF(6<=$C$8,ROUND('Child 1'!$O$70+'Child 2'!$O$70+'Child 3'!$O$70+'Child 4'!$O$70,2),"") | G37: =IF(6<=$C$8,ROUND('Child 1'!$D$70+'Child 2'!$D$70+'Child 3'!$D$70+'Child 4'!$D$70,2),"") | H37: =IF(6<=$C$8,ROUND('Child 1'!$P$70+'Child 2'!$P$70+'Child 3'!$P$70+'Child 4'!$P$70,2),"") | T37: =IF(6<=$C$8,B37,"") | U37: =IF(6<=$C$8,'Child 1'!$D$70,NA()) -> #N/A | V37: =IF(6<=$C$8,'Child 2'!$D$70,NA()) -> #N/A | W37: =IF(6<=$C$8,'Child 3'!$D$70,NA()) -> #N/A | X37: =IF(6<=$C$8,'Child 4'!$D$70,NA()) -> #N/A | Y37: =IF(6<=$C$8,E37,NA()) -> #N/A
B38: =IF(7<=$C$8,(PlanYear+6)&"/"&RIGHT(PlanYear+7,2),"") | C38: =IF(7<=$C$8,MID(IF('Child 1'!$Q$71=1,", "&IF(Inputs!$C$14<>"",Inputs!$C$14,"Child 1"),"")&IF('Child 2'!$Q$71=1,", "&IF(Inputs!$D$14<>"",Inputs!$D$14,"Child 2"),"")&IF('Child 3'!$Q$71=1,", "&IF(Inputs!$E$14<>"",Inputs!$E$14,"Child 3"),"")&IF('Child 4'!$Q$71=1,", "&IF(Inputs!$F$14<>"",Inputs!$F$14,"Child 4"),""),3,200),"") | D38: =IF(7<=$C$8,ROUND('Child 1'!$M$71+'Child 2'!$M$71+'Child 3'!$M$71+'Child 4'!$M$71,2),"") | E38: =IF(7<=$C$8,ROUND('Child 1'!$N$71+'Child 2'!$N$71+'Child 3'!$N$71+'Child 4'!$N$71,2),"") | F38: =IF(7<=$C$8,ROUND('Child 1'!$O$71+'Child 2'!$O$71+'Child 3'!$O$71+'Child 4'!$O$71,2),"") | G38: =IF(7<=$C$8,ROUND('Child 1'!$D$71+'Child 2'!$D$71+'Child 3'!$D$71+'Child 4'!$D$71,2),"") | H38: =IF(7<=$C$8,ROUND('Child 1'!$P$71+'Child 2'!$P$71+'Child 3'!$P$71+'Child 4'!$P$71,2),"") | T38: =IF(7<=$C$8,B38,"") | U38: =IF(7<=$C$8,'Child 1'!$D$71,NA()) -> #N/A | V38: =IF(7<=$C$8,'Child 2'!$D$71,NA()) -> #N/A | W38: =IF(7<=$C$8,'Child 3'!$D$71,NA()) -> #N/A | X38: =IF(7<=$C$8,'Child 4'!$D$71,NA()) -> #N/A | Y38: =IF(7<=$C$8,E38,NA()) -> #N/A
B39: =IF(8<=$C$8,(PlanYear+7)&"/"&RIGHT(PlanYear+8,2),"") | C39: =IF(8<=$C$8,MID(IF('Child 1'!$Q$72=1,", "&IF(Inputs!$C$14<>"",Inputs!$C$14,"Child 1"),"")&IF('Child 2'!$Q$72=1,", "&IF(Inputs!$D$14<>"",Inputs!$D$14,"Child 2"),"")&IF('Child 3'!$Q$72=1,", "&IF(Inputs!$E$14<>"",Inputs!$E$14,"Child 3"),"")&IF('Child 4'!$Q$72=1,", "&IF(Inputs!$F$14<>"",Inputs!$F$14,"Child 4"),""),3,200),"") | D39: =IF(8<=$C$8,ROUND('Child 1'!$M$72+'Child 2'!$M$72+'Child 3'!$M$72+'Child 4'!$M$72,2),"") | E39: =IF(8<=$C$8,ROUND('Child 1'!$N$72+'Child 2'!$N$72+'Child 3'!$N$72+'Child 4'!$N$72,2),"") | F39: =IF(8<=$C$8,ROUND('Child 1'!$O$72+'Child 2'!$O$72+'Child 3'!$O$72+'Child 4'!$O$72,2),"") | G39: =IF(8<=$C$8,ROUND('Child 1'!$D$72+'Child 2'!$D$72+'Child 3'!$D$72+'Child 4'!$D$72,2),"") | H39: =IF(8<=$C$8,ROUND('Child 1'!$P$72+'Child 2'!$P$72+'Child 3'!$P$72+'Child 4'!$P$72,2),"") | T39: =IF(8<=$C$8,B39,"") | U39: =IF(8<=$C$8,'Child 1'!$D$72,NA()) -> #N/A | V39: =IF(8<=$C$8,'Child 2'!$D$72,NA()) -> #N/A | W39: =IF(8<=$C$8,'Child 3'!$D$72,NA()) -> #N/A | X39: =IF(8<=$C$8,'Child 4'!$D$72,NA()) -> #N/A | Y39: =IF(8<=$C$8,E39,NA()) -> #N/A
B40: =IF(9<=$C$8,(PlanYear+8)&"/"&RIGHT(PlanYear+9,2),"") | C40: =IF(9<=$C$8,MID(IF('Child 1'!$Q$73=1,", "&IF(Inputs!$C$14<>"",Inputs!$C$14,"Child 1"),"")&IF('Child 2'!$Q$73=1,", "&IF(Inputs!$D$14<>"",Inputs!$D$14,"Child 2"),"")&IF('Child 3'!$Q$73=1,", "&IF(Inputs!$E$14<>"",Inputs!$E$14,"Child 3"),"")&IF('Child 4'!$Q$73=1,", "&IF(Inputs!$F$14<>"",Inputs!$F$14,"Child 4"),""),3,200),"") | D40: =IF(9<=$C$8,ROUND('Child 1'!$M$73+'Child 2'!$M$73+'Child 3'!$M$73+'Child 4'!$M$73,2),"") | E40: =IF(9<=$C$8,ROUND('Child 1'!$N$73+'Child 2'!$N$73+'Child 3'!$N$73+'Child 4'!$N$73,2),"") | F40: =IF(9<=$C$8,ROUND('Child 1'!$O$73+'Child 2'!$O$73+'Child 3'!$O$73+'Child 4'!$O$73,2),"") | G40: =IF(9<=$C$8,ROUND('Child 1'!$D$73+'Child 2'!$D$73+'Child 3'!$D$73+'Child 4'!$D$73,2),"") | H40: =IF(9<=$C$8,ROUND('Child 1'!$P$73+'Child 2'!$P$73+'Child 3'!$P$73+'Child 4'!$P$73,2),"") | T40: =IF(9<=$C$8,B40,"") | U40: =IF(9<=$C$8,'Child 1'!$D$73,NA()) -> #N/A | V40: =IF(9<=$C$8,'Child 2'!$D$73,NA()) -> #N/A | W40: =IF(9<=$C$8,'Child 3'!$D$73,NA()) -> #N/A | X40: =IF(9<=$C$8,'Child 4'!$D$73,NA()) -> #N/A | Y40: =IF(9<=$C$8,E40,NA()) -> #N/A
B41: =IF(10<=$C$8,(PlanYear+9)&"/"&RIGHT(PlanYear+10,2),"") | C41: =IF(10<=$C$8,MID(IF('Child 1'!$Q$74=1,", "&IF(Inputs!$C$14<>"",Inputs!$C$14,"Child 1"),"")&IF('Child 2'!$Q$74=1,", "&IF(Inputs!$D$14<>"",Inputs!$D$14,"Child 2"),"")&IF('Child 3'!$Q$74=1,", "&IF(Inputs!$E$14<>"",Inputs!$E$14,"Child 3"),"")&IF('Child 4'!$Q$74=1,", "&IF(Inputs!$F$14<>"",Inputs!$F$14,"Child 4"),""),3,200),"") | D41: =IF(10<=$C$8,ROUND('Child 1'!$M$74+'Child 2'!$M$74+'Child 3'!$M$74+'Child 4'!$M$74,2),"") | E41: =IF(10<=$C$8,ROUND('Child 1'!$N$74+'Child 2'!$N$74+'Child 3'!$N$74+'Child 4'!$N$74,2),"") | F41: =IF(10<=$C$8,ROUND('Child 1'!$O$74+'Child 2'!$O$74+'Child 3'!$O$74+'Child 4'!$O$74,2),"") | G41: =IF(10<=$C$8,ROUND('Child 1'!$D$74+'Child 2'!$D$74+'Child 3'!$D$74+'Child 4'!$D$74,2),"") | H41: =IF(10<=$C$8,ROUND('Child 1'!$P$74+'Child 2'!$P$74+'Child 3'!$P$74+'Child 4'!$P$74,2),"") | T41: =IF(10<=$C$8,B41,"") | U41: =IF(10<=$C$8,'Child 1'!$D$74,NA()) -> #N/A | V41: =IF(10<=$C$8,'Child 2'!$D$74,NA()) -> #N/A | W41: =IF(10<=$C$8,'Child 3'!$D$74,NA()) -> #N/A | X41: =IF(10<=$C$8,'Child 4'!$D$74,NA()) -> #N/A | Y41: =IF(10<=$C$8,E41,NA()) -> #N/A
B42: =IF(11<=$C$8,(PlanYear+10)&"/"&RIGHT(PlanYear+11,2),"") | C42: =IF(11<=$C$8,MID(IF('Child 1'!$Q$75=1,", "&IF(Inputs!$C$14<>"",Inputs!$C$14,"Child 1"),"")&IF('Child 2'!$Q$75=1,", "&IF(Inputs!$D$14<>"",Inputs!$D$14,"Child 2"),"")&IF('Child 3'!$Q$75=1,", "&IF(Inputs!$E$14<>"",Inputs!$E$14,"Child 3"),"")&IF('Child 4'!$Q$75=1,", "&IF(Inputs!$F$14<>"",Inputs!$F$14,"Child 4"),""),3,200),"") | D42: =IF(11<=$C$8,ROUND('Child 1'!$M$75+'Child 2'!$M$75+'Child 3'!$M$75+'Child 4'!$M$75,2),"") | E42: =IF(11<=$C$8,ROUND('Child 1'!$N$75+'Child 2'!$N$75+'Child 3'!$N$75+'Child 4'!$N$75,2),"") | F42: =IF(11<=$C$8,ROUND('Child 1'!$O$75+'Child 2'!$O$75+'Child 3'!$O$75+'Child 4'!$O$75,2),"") | G42: =IF(11<=$C$8,ROUND('Child 1'!$D$75+'Child 2'!$D$75+'Child 3'!$D$75+'Child 4'!$D$75,2),"") | H42: =IF(11<=$C$8,ROUND('Child 1'!$P$75+'Child 2'!$P$75+'Child 3'!$P$75+'Child 4'!$P$75,2),"") | T42: =IF(11<=$C$8,B42,"") | U42: =IF(11<=$C$8,'Child 1'!$D$75,NA()) -> #N/A | V42: =IF(11<=$C$8,'Child 2'!$D$75,NA()) -> #N/A | W42: =IF(11<=$C$8,'Child 3'!$D$75,NA()) -> #N/A | X42: =IF(11<=$C$8,'Child 4'!$D$75,NA()) -> #N/A | Y42: =IF(11<=$C$8,E42,NA()) -> #N/A
B43: =IF(12<=$C$8,(PlanYear+11)&"/"&RIGHT(PlanYear+12,2),"") | C43: =IF(12<=$C$8,MID(IF('Child 1'!$Q$76=1,", "&IF(Inputs!$C$14<>"",Inputs!$C$14,"Child 1"),"")&IF('Child 2'!$Q$76=1,", "&IF(Inputs!$D$14<>"",Inputs!$D$14,"Child 2"),"")&IF('Child 3'!$Q$76=1,", "&IF(Inputs!$E$14<>"",Inputs!$E$14,"Child 3"),"")&IF('Child 4'!$Q$76=1,", "&IF(Inputs!$F$14<>"",Inputs!$F$14,"Child 4"),""),3,200),"") | D43: =IF(12<=$C$8,ROUND('Child 1'!$M$76+'Child 2'!$M$76+'Child 3'!$M$76+'Child 4'!$M$76,2),"") | E43: =IF(12<=$C$8,ROUND('Child 1'!$N$76+'Child 2'!$N$76+'Child 3'!$N$76+'Child 4'!$N$76,2),"") | F43: =IF(12<=$C$8,ROUND('Child 1'!$O$76+'Child 2'!$O$76+'Child 3'!$O$76+'Child 4'!$O$76,2),"") | G43: =IF(12<=$C$8,ROUND('Child 1'!$D$76+'Child 2'!$D$76+'Child 3'!$D$76+'Child 4'!$D$76,2),"") | H43: =IF(12<=$C$8,ROUND('Child 1'!$P$76+'Child 2'!$P$76+'Child 3'!$P$76+'Child 4'!$P$76,2),"") | T43: =IF(12<=$C$8,B43,"") | U43: =IF(12<=$C$8,'Child 1'!$D$76,NA()) -> #N/A | V43: =IF(12<=$C$8,'Child 2'!$D$76,NA()) -> #N/A | W43: =IF(12<=$C$8,'Child 3'!$D$76,NA()) -> #N/A | X43: =IF(12<=$C$8,'Child 4'!$D$76,NA()) -> #N/A | Y43: =IF(12<=$C$8,E43,NA()) -> #N/A
B44: =IF(13<=$C$8,(PlanYear+12)&"/"&RIGHT(PlanYear+13,2),"") | C44: =IF(13<=$C$8,MID(IF('Child 1'!$Q$77=1,", "&IF(Inputs!$C$14<>"",Inputs!$C$14,"Child 1"),"")&IF('Child 2'!$Q$77=1,", "&IF(Inputs!$D$14<>"",Inputs!$D$14,"Child 2"),"")&IF('Child 3'!$Q$77=1,", "&IF(Inputs!$E$14<>"",Inputs!$E$14,"Child 3"),"")&IF('Child 4'!$Q$77=1,", "&IF(Inputs!$F$14<>"",Inputs!$F$14,"Child 4"),""),3,200),"") | D44: =IF(13<=$C$8,ROUND('Child 1'!$M$77+'Child 2'!$M$77+'Child 3'!$M$77+'Child 4'!$M$77,2),"") | E44: =IF(13<=$C$8,ROUND('Child 1'!$N$77+'Child 2'!$N$77+'Child 3'!$N$77+'Child 4'!$N$77,2),"") | F44: =IF(13<=$C$8,ROUND('Child 1'!$O$77+'Child 2'!$O$77+'Child 3'!$O$77+'Child 4'!$O$77,2),"") | G44: =IF(13<=$C$8,ROUND('Child 1'!$D$77+'Child 2'!$D$77+'Child 3'!$D$77+'Child 4'!$D$77,2),"") | H44: =IF(13<=$C$8,ROUND('Child 1'!$P$77+'Child 2'!$P$77+'Child 3'!$P$77+'Child 4'!$P$77,2),"") | T44: =IF(13<=$C$8,B44,"") | U44: =IF(13<=$C$8,'Child 1'!$D$77,NA()) -> #N/A | V44: =IF(13<=$C$8,'Child 2'!$D$77,NA()) -> #N/A | W44: =IF(13<=$C$8,'Child 3'!$D$77,NA()) -> #N/A | X44: =IF(13<=$C$8,'Child 4'!$D$77,NA()) -> #N/A | Y44: =IF(13<=$C$8,E44,NA()) -> #N/A
...

Sheet Compare Countries
B1: Compare countries
B2: ="The same child and qualification in each country, in "&RepCcy&". Choose the child on the Inputs sheet (Compare countries for child number)." -> The same child and qualification in each country, in USD. Choose the child on the Inputs sheet (Compare countries for child number).
B4: Child | C4: =CHOOSE(CmpChild,IF(Inputs!$C$14<>"",Inputs!$C$14,"Child 1"),IF(Inputs!$D$14<>"",Inputs!$D$14,"Child 2"),IF(Inputs!$E$14<>"",Inputs!$E$14,"Child 3"),IF(Inputs!$F$14<>"",Inputs!$F$14,"Child 4")) -> Child 1
B5: Qualification | C5: =CHOOSE(CmpChild,'Child 1'!$B$6,'Child 2'!$B$6,'Child 3'!$B$6,'Child 4'!$B$6)
B6: Current plan | C6: =IF(CHOOSE(CmpChild,'Child 1'!$B$22,'Child 2'!$B$22,'Child 3'!$B$22,'Child 4'!$B$22)=1,CHOOSE(CmpChild,'Child 1'!$B$5,'Child 2'!$B$5,'Child 3'!$B$5,'Child 4'!$B$5),"Enter this child's details on the Inputs sheet first.") -> Enter this child's details on the Inputs sheet first.
B8: Country | C8: ="Total ("&RepCcy&")" -> Total (USD) | D8: Note | E8: Current plan
B9: Pakistan | C9: =IF(CHOOSE(CmpChild,'Child 1'!$B$22,'Child 2'!$B$22,'Child 3'!$B$22,'Child 4'!$B$22)<>1,"",IF(CHOOSE(CmpChild,'Child 1'!$B$5,'Child 2'!$B$5,'Child 3'!$B$5,'Child 4'!$B$5)="Pakistan",CHOOSE(CmpChild,'Child 1'!$Z$56,'Child 2'!$Z$56,'Child 3'!$Z$56,'Child 4'!$Z$56),IF('Compare Calc'!$B$21=1,'Compare Calc'!$Z$55,"Not available"))) | D9: =IF(CHOOSE(CmpChild,'Child 1'!$B$22,'Child 2'!$B$22,'Child 3'!$B$22,'Child 4'!$B$22)<>1,"",IF(AND(NOT(CHOOSE(CmpChild,'Child 1'!$B$5,'Child 2'!$B$5,'Child 3'!$B$5,'Child 4'!$B$5)="Pakistan"),'Compare Calc'!$B$21<>1),'Compare Calc'!$B$22,IF(IF(CHOOSE(CmpChild,'Child 1'!$B$5,'Child 2'!$B$5,'Child 3'!$B$5,'Child 4'!$B$5)="Pakistan",CHOOSE(CmpChild,'Child 1'!$B$60,'Child 2'!$B$60,'Child 3'!$B$60,'Child 4'!$B$60),'Compare Calc'!$B$59)="estimated","Estimate — no published fee for this course",IF(IF(CHOOSE(CmpChild,'Child 1'!$B$5,'Child 2'!$B$5,'Child 3'!$B$5,'Child 4'!$B$5)="Pakistan",CHOOSE(CmpChild,'Child 1'!$B$61,'Child 2'!$B$61,'Child 3'!$B$61,'Child 4'!$B$61),'Compare Calc'!$B$60)=1,"Some costs have no figure yet","")))) | E9: =IF(AND(CHOOSE(CmpChild,'Child 1'!$B$22,'Child 2'!$B$22,'Child 3'!$B$22,'Child 4'!$B$22)=1,CHOOSE(CmpChild,'Child 1'!$B$5,'Child 2'!$B$5,'Child 3'!$B$5,'Child 4'!$B$5)="Pakistan"),"Current plan","")
B10: India | C10: =IF(CHOOSE(CmpChild,'Child 1'!$B$22,'Child 2'!$B$22,'Child 3'!$B$22,'Child 4'!$B$22)<>1,"",IF(CHOOSE(CmpChild,'Child 1'!$B$5,'Child 2'!$B$5,'Child 3'!$B$5,'Child 4'!$B$5)="India",CHOOSE(CmpChild,'Child 1'!$Z$56,'Child 2'!$Z$56,'Child 3'!$Z$56,'Child 4'!$Z$56),IF('Compare Calc'!$B$82=1,'Compare Calc'!$Z$116,"Not available"))) | D10: =IF(CHOOSE(CmpChild,'Child 1'!$B$22,'Child 2'!$B$22,'Child 3'!$B$22,'Child 4'!$B$22)<>1,"",IF(AND(NOT(CHOOSE(CmpChild,'Child 1'!$B$5,'Child 2'!$B$5,'Child 3'!$B$5,'Child 4'!$B$5)="India"),'Compare Calc'!$B$82<>1),'Compare Calc'!$B$83,IF(IF(CHOOSE(CmpChild,'Child 1'!$B$5,'Child 2'!$B$5,'Child 3'!$B$5,'Child 4'!$B$5)="India",CHOOSE(CmpChild,'Child 1'!$B$60,'Child 2'!$B$60,'Child 3'!$B$60,'Child 4'!$B$60),'Compare Calc'!$B$120)="estimated","Estimate — no published fee for this course",IF(IF(CHOOSE(CmpChild,'Child 1'!$B$5,'Child 2'!$B$5,'Child 3'!$B$5,'Child 4'!$B$5)="India",CHOOSE(CmpChild,'Child 1'!$B$61,'Child 2'!$B$61,'Child 3'!$B$61,'Child 4'!$B$61),'Compare Calc'!$B$121)=1,"Some costs have no figure yet","")))) | E10: =IF(AND(CHOOSE(CmpChild,'Child 1'!$B$22,'Child 2'!$B$22,'Child 3'!$B$22,'Child 4'!$B$22)=1,CHOOSE(CmpChild,'Child 1'!$B$5,'Child 2'!$B$5,'Child 3'!$B$5,'Child 4'!$B$5)="India"),"Current plan","")
B11: USA | C11: =IF(CHOOSE(CmpChild,'Child 1'!$B$22,'Child 2'!$B$22,'Child 3'!$B$22,'Child 4'!$B$22)<>1,"",IF(CHOOSE(CmpChild,'Child 1'!$B$5,'Child 2'!$B$5,'Child 3'!$B$5,'Child 4'!$B$5)="USA",CHOOSE(CmpChild,'Child 1'!$Z$56,'Child 2'!$Z$56,'Child 3'!$Z$56,'Child 4'!$Z$56),IF('Compare Calc'!$B$143=1,'Compare Calc'!$Z$177,"Not available"))) | D11: =IF(CHOOSE(CmpChild,'Child 1'!$B$22,'Child 2'!$B$22,'Child 3'!$B$22,'Child 4'!$B$22)<>1,"",IF(AND(NOT(CHOOSE(CmpChild,'Child 1'!$B$5,'Child 2'!$B$5,'Child 3'!$B$5,'Child 4'!$B$5)="USA"),'Compare Calc'!$B$143<>1),'Compare Calc'!$B$144,IF(IF(CHOOSE(CmpChild,'Child 1'!$B$5,'Child 2'!$B$5,'Child 3'!$B$5,'Child 4'!$B$5)="USA",CHOOSE(CmpChild,'Child 1'!$B$60,'Child 2'!$B$60,'Child 3'!$B$60,'Child 4'!$B$60),'Compare Calc'!$B$181)="estimated","Estimate — no published fee for this course",IF(IF(CHOOSE(CmpChild,'Child 1'!$B$5,'Child 2'!$B$5,'Child 3'!$B$5,'Child 4'!$B$5)="USA",CHOOSE(CmpChild,'Child 1'!$B$61,'Child 2'!$B$61,'Child 3'!$B$61,'Child 4'!$B$61),'Compare Calc'!$B$182)=1,"Some costs have no figure yet","")))) | E11: =IF(AND(CHOOSE(CmpChild,'Child 1'!$B$22,'Child 2'!$B$22,'Child 3'!$B$22,'Child 4'!$B$22)=1,CHOOSE(CmpChild,'Child 1'!$B$5,'Child 2'!$B$5,'Child 3'!$B$5,'Child 4'!$B$5)="USA"),"Current plan","")
B12: UK | C12: =IF(CHOOSE(CmpChild,'Child 1'!$B$22,'Child 2'!$B$22,'Child 3'!$B$22,'Child 4'!$B$22)<>1,"",IF(CHOOSE(CmpChild,'Child 1'!$B$5,'Child 2'!$B$5,'Child 3'!$B$5,'Child 4'!$B$5)="UK",CHOOSE(CmpChild,'Child 1'!$Z$56,'Child 2'!$Z$56,'Child 3'!$Z$56,'Child 4'!$Z$56),IF('Compare Calc'!$B$204=1,'Compare Calc'!$Z$238,"Not available"))) | D12: =IF(CHOOSE(CmpChild,'Child 1'!$B$22,'Child 2'!$B$22,'Child 3'!$B$22,'Child 4'!$B$22)<>1,"",IF(AND(NOT(CHOOSE(CmpChild,'Child 1'!$B$5,'Child 2'!$B$5,'Child 3'!$B$5,'Child 4'!$B$5)="UK"),'Compare Calc'!$B$204<>1),'Compare Calc'!$B$205,IF(IF(CHOOSE(CmpChild,'Child 1'!$B$5,'Child 2'!$B$5,'Child 3'!$B$5,'Child 4'!$B$5)="UK",CHOOSE(CmpChild,'Child 1'!$B$60,'Child 2'!$B$60,'Child 3'!$B$60,'Child 4'!$B$60),'Compare Calc'!$B$242)="estimated","Estimate — no published fee for this course",IF(IF(CHOOSE(CmpChild,'Child 1'!$B$5,'Child 2'!$B$5,'Child 3'!$B$5,'Child 4'!$B$5)="UK",CHOOSE(CmpChild,'Child 1'!$B$61,'Child 2'!$B$61,'Child 3'!$B$61,'Child 4'!$B$61),'Compare Calc'!$B$243)=1,"Some costs have no figure yet","")))) | E12: =IF(AND(CHOOSE(CmpChild,'Child 1'!$B$22,'Child 2'!$B$22,'Child 3'!$B$22,'Child 4'!$B$22)=1,CHOOSE(CmpChild,'Child 1'!$B$5,'Child 2'!$B$5,'Child 3'!$B$5,'Child 4'!$B$5)="UK"),"Current plan","")
B13: Australia | C13: =IF(CHOOSE(CmpChild,'Child 1'!$B$22,'Child 2'!$B$22,'Child 3'!$B$22,'Child 4'!$B$22)<>1,"",IF(CHOOSE(CmpChild,'Child 1'!$B$5,'Child 2'!$B$5,'Child 3'!$B$5,'Child 4'!$B$5)="Australia",CHOOSE(CmpChild,'Child 1'!$Z$56,'Child 2'!$Z$56,'Child 3'!$Z$56,'Child 4'!$Z$56),IF('Compare Calc'!$B$265=1,'Compare Calc'!$Z$299,"Not available"))) | D13: =IF(CHOOSE(CmpChild,'Child 1'!$B$22,'Child 2'!$B$22,'Child 3'!$B$22,'Child 4'!$B$22)<>1,"",IF(AND(NOT(CHOOSE(CmpChild,'Child 1'!$B$5,'Child 2'!$B$5,'Child 3'!$B$5,'Child 4'!$B$5)="Australia"),'Compare Calc'!$B$265<>1),'Compare Calc'!$B$266,IF(IF(CHOOSE(CmpChild,'Child 1'!$B$5,'Child 2'!$B$5,'Child 3'!$B$5,'Child 4'!$B$5)="Australia",CHOOSE(CmpChild,'Child 1'!$B$60,'Child 2'!$B$60,'Child 3'!$B$60,'Child 4'!$B$60),'Compare Calc'!$B$303)="estimated","Estimate — no published fee for this course",IF(IF(CHOOSE(CmpChild,'Child 1'!$B$5,'Child 2'!$B$5,'Child 3'!$B$5,'Child 4'!$B$5)="Australia",CHOOSE(CmpChild,'Child 1'!$B$61,'Child 2'!$B$61,'Child 3'!$B$61,'Child 4'!$B$61),'Compare Calc'!$B$304)=1,"Some costs have no figure yet","")))) | E13: =IF(AND(CHOOSE(CmpChild,'Child 1'!$B$22,'Child 2'!$B$22,'Child 3'!$B$22,'Child 4'!$B$22)=1,CHOOSE(CmpChild,'Child 1'!$B$5,'Child 2'!$B$5,'Child 3'!$B$5,'Child 4'!$B$5)="Australia"),"Current plan","")
B14: Germany | C14: =IF(CHOOSE(CmpChild,'Child 1'!$B$22,'Child 2'!$B$22,'Child 3'!$B$22,'Child 4'!$B$22)<>1,"",IF(CHOOSE(CmpChild,'Child 1'!$B$5,'Child 2'!$B$5,'Child 3'!$B$5,'Child 4'!$B$5)="Germany",CHOOSE(CmpChild,'Child 1'!$Z$56,'Child 2'!$Z$56,'Child 3'!$Z$56,'Child 4'!$Z$56),IF('Compare Calc'!$B$326=1,'Compare Calc'!$Z$360,"Not available"))) | D14: =IF(CHOOSE(CmpChild,'Child 1'!$B$22,'Child 2'!$B$22,'Child 3'!$B$22,'Child 4'!$B$22)<>1,"",IF(AND(NOT(CHOOSE(CmpChild,'Child 1'!$B$5,'Child 2'!$B$5,'Child 3'!$B$5,'Child 4'!$B$5)="Germany"),'Compare Calc'!$B$326<>1),'Compare Calc'!$B$327,IF(IF(CHOOSE(CmpChild,'Child 1'!$B$5,'Child 2'!$B$5,'Child 3'!$B$5,'Child 4'!$B$5)="Germany",CHOOSE(CmpChild,'Child 1'!$B$60,'Child 2'!$B$60,'Child 3'!$B$60,'Child 4'!$B$60),'Compare Calc'!$B$364)="estimated","Estimate — no published fee for this course",IF(IF(CHOOSE(CmpChild,'Child 1'!$B$5,'Child 2'!$B$5,'Child 3'!$B$5,'Child 4'!$B$5)="Germany",CHOOSE(CmpChild,'Child 1'!$B$61,'Child 2'!$B$61,'Child 3'!$B$61,'Child 4'!$B$61),'Compare Calc'!$B$365)=1,"Some costs have no figure yet","")))) | E14: =IF(AND(CHOOSE(CmpChild,'Child 1'!$B$22,'Child 2'!$B$22,'Child 3'!$B$22,'Child 4'!$B$22)=1,CHOOSE(CmpChild,'Child 1'!$B$5,'Child 2'!$B$5,'Child 3'!$B$5,'Child 4'!$B$5)="Germany"),"Current plan","")
B15: Singapore | C15: =IF(CHOOSE(CmpChild,'Child 1'!$B$22,'Child 2'!$B$22,'Child 3'!$B$22,'Child 4'!$B$22)<>1,"",IF(CHOOSE(CmpChild,'Child 1'!$B$5,'Child 2'!$B$5,'Child 3'!$B$5,'Child 4'!$B$5)="Singapore",CHOOSE(CmpChild,'Child 1'!$Z$56,'Child 2'!$Z$56,'Child 3'!$Z$56,'Child 4'!$Z$56),IF('Compare Calc'!$B$387=1,'Compare Calc'!$Z$421,"Not available"))) | D15: =IF(CHOOSE(CmpChild,'Child 1'!$B$22,'Child 2'!$B$22,'Child 3'!$B$22,'Child 4'!$B$22)<>1,"",IF(AND(NOT(CHOOSE(CmpChild,'Child 1'!$B$5,'Child 2'!$B$5,'Child 3'!$B$5,'Child 4'!$B$5)="Singapore"),'Compare Calc'!$B$387<>1),'Compare Calc'!$B$388,IF(IF(CHOOSE(CmpChild,'Child 1'!$B$5,'Child 2'!$B$5,'Child 3'!$B$5,'Child 4'!$B$5)="Singapore",CHOOSE(CmpChild,'Child 1'!$B$60,'Child 2'!$B$60,'Child 3'!$B$60,'Child 4'!$B$60),'Compare Calc'!$B$425)="estimated","Estimate — no published fee for this course",IF(IF(CHOOSE(CmpChild,'Child 1'!$B$5,'Child 2'!$B$5,'Child 3'!$B$5,'Child 4'!$B$5)="Singapore",CHOOSE(CmpChild,'Child 1'!$B$61,'Child 2'!$B$61,'Child 3'!$B$61,'Child 4'!$B$61),'Compare Calc'!$B$426)=1,"Some costs have no figure yet","")))) | E15: =IF(AND(CHOOSE(CmpChild,'Child 1'!$B$22,'Child 2'!$B$22,'Child 3'!$B$22,'Child 4'!$B$22)=1,CHOOSE(CmpChild,'Child 1'!$B$5,'Child 2'!$B$5,'Child 3'!$B$5,'Child 4'!$B$5)="Singapore"),"Current plan","")
B16: Malaysia | C16: =IF(CHOOSE(CmpChild,'Child 1'!$B$22,'Child 2'!$B$22,'Child 3'!$B$22,'Child 4'!$B$22)<>1,"",IF(CHOOSE(CmpChild,'Child 1'!$B$5,'Child 2'!$B$5,'Child 3'!$B$5,'Child 4'!$B$5)="Malaysia",CHOOSE(CmpChild,'Child 1'!$Z$56,'Child 2'!$Z$56,'Child 3'!$Z$56,'Child 4'!$Z$56),IF('Compare Calc'!$B$448=1,'Compare Calc'!$Z$482,"Not available"))) | D16: =IF(CHOOSE(CmpChild,'Child 1'!$B$22,'Child 2'!$B$22,'Child 3'!$B$22,'Child 4'!$B$22)<>1,"",IF(AND(NOT(CHOOSE(CmpChild,'Child 1'!$B$5,'Child 2'!$B$5,'Child 3'!$B$5,'Child 4'!$B$5)="Malaysia"),'Compare Calc'!$B$448<>1),'Compare Calc'!$B$449,IF(IF(CHOOSE(CmpChild,'Child 1'!$B$5,'Child 2'!$B$5,'Child 3'!$B$5,'Child 4'!$B$5)="Malaysia",CHOOSE(CmpChild,'Child 1'!$B$60,'Child 2'!$B$60,'Child 3'!$B$60,'Child 4'!$B$60),'Compare Calc'!$B$486)="estimated","Estimate — no published fee for this course",IF(IF(CHOOSE(CmpChild,'Child 1'!$B$5,'Child 2'!$B$5,'Child 3'!$B$5,'Child 4'!$B$5)="Malaysia",CHOOSE(CmpChild,'Child 1'!$B$61,'Child 2'!$B$61,'Child 3'!$B$61,'Child 4'!$B$61),'Compare Calc'!$B$487)=1,"Some costs have no figure yet","")))) | E16: =IF(AND(CHOOSE(CmpChild,'Child 1'!$B$22,'Child 2'!$B$22,'Child 3'!$B$22,'Child 4'!$B$22)=1,CHOOSE(CmpChild,'Child 1'!$B$5,'Child 2'!$B$5,'Child 3'!$B$5,'Child 4'!$B$5)="Malaysia"),"Current plan","")
B17: Ireland | C17: =IF(CHOOSE(CmpChild,'Child 1'!$B$22,'Child 2'!$B$22,'Child 3'!$B$22,'Child 4'!$B$22)<>1,"",IF(CHOOSE(CmpChild,'Child 1'!$B$5,'Child 2'!$B$5,'Child 3'!$B$5,'Child 4'!$B$5)="Ireland",CHOOSE(CmpChild,'Child 1'!$Z$56,'Child 2'!$Z$56,'Child 3'!$Z$56,'Child 4'!$Z$56),IF('Compare Calc'!$B$509=1,'Compare Calc'!$Z$543,"Not available"))) | D17: =IF(CHOOSE(CmpChild,'Child 1'!$B$22,'Child 2'!$B$22,'Child 3'!$B$22,'Child 4'!$B$22)<>1,"",IF(AND(NOT(CHOOSE(CmpChild,'Child 1'!$B$5,'Child 2'!$B$5,'Child 3'!$B$5,'Child 4'!$B$5)="Ireland"),'Compare Calc'!$B$509<>1),'Compare Calc'!$B$510,IF(IF(CHOOSE(CmpChild,'Child 1'!$B$5,'Child 2'!$B$5,'Child 3'!$B$5,'Child 4'!$B$5)="Ireland",CHOOSE(CmpChild,'Child 1'!$B$60,'Child 2'!$B$60,'Child 3'!$B$60,'Child 4'!$B$60),'Compare Calc'!$B$547)="estimated","Estimate — no published fee for this course",IF(IF(CHOOSE(CmpChild,'Child 1'!$B$5,'Child 2'!$B$5,'Child 3'!$B$5,'Child 4'!$B$5)="Ireland",CHOOSE(CmpChild,'Child 1'!$B$61,'Child 2'!$B$61,'Child 3'!$B$61,'Child 4'!$B$61),'Compare Calc'!$B$548)=1,"Some costs have no figure yet","")))) | E17: =IF(AND(CHOOSE(CmpChild,'Child 1'!$B$22,'Child 2'!$B$22,'Child 3'!$B$22,'Child 4'!$B$22)=1,CHOOSE(CmpChild,'Child 1'!$B$5,'Child 2'!$B$5,'Child 3'!$B$5,'Child 4'!$B$5)="Ireland"),"Current plan","")
B18: Qatar | C18: =IF(CHOOSE(CmpChild,'Child 1'!$B$22,'Child 2'!$B$22,'Child 3'!$B$22,'Child 4'!$B$22)<>1,"",IF(CHOOSE(CmpChild,'Child 1'!$B$5,'Child 2'!$B$5,'Child 3'!$B$5,'Child 4'!$B$5)="Qatar",CHOOSE(CmpChild,'Child 1'!$Z$56,'Child 2'!$Z$56,'Child 3'!$Z$56,'Child 4'!$Z$56),IF('Compare Calc'!$B$570=1,'Compare Calc'!$Z$604,"Not available"))) | D18: =IF(CHOOSE(CmpChild,'Child 1'!$B$22,'Child 2'!$B$22,'Child 3'!$B$22,'Child 4'!$B$22)<>1,"",IF(AND(NOT(CHOOSE(CmpChild,'Child 1'!$B$5,'Child 2'!$B$5,'Child 3'!$B$5,'Child 4'!$B$5)="Qatar"),'Compare Calc'!$B$570<>1),'Compare Calc'!$B$571,IF(IF(CHOOSE(CmpChild,'Child 1'!$B$5,'Child 2'!$B$5,'Child 3'!$B$5,'Child 4'!$B$5)="Qatar",CHOOSE(CmpChild,'Child 1'!$B$60,'Child 2'!$B$60,'Child 3'!$B$60,'Child 4'!$B$60),'Compare Calc'!$B$608)="estimated","Estimate — no published fee for this course",IF(IF(CHOOSE(CmpChild,'Child 1'!$B$5,'Child 2'!$B$5,'Child 3'!$B$5,'Child 4'!$B$5)="Qatar",CHOOSE(CmpChild,'Child 1'!$B$61,'Child 2'!$B$61,'Child 3'!$B$61,'Child 4'!$B$61),'Compare Calc'!$B$609)=1,"Some costs have no figure yet","")))) | E18: =IF(AND(CHOOSE(CmpChild,'Child 1'!$B$22,'Child 2'!$B$22,'Child 3'!$B$22,'Child 4'!$B$22)=1,CHOOSE(CmpChild,'Child 1'!$B$5,'Child 2'!$B$5,'Child 3'!$B$5,'Child 4'!$B$5)="Qatar"),"Current plan","")
B19: United Arab Emirates | C19: =IF(CHOOSE(CmpChild,'Child 1'!$B$22,'Child 2'!$B$22,'Child 3'!$B$22,'Child 4'!$B$22)<>1,"",IF(CHOOSE(CmpChild,'Child 1'!$B$5,'Child 2'!$B$5,'Child 3'!$B$5,'Child 4'!$B$5)="United Arab Emirates",CHOOSE(CmpChild,'Child 1'!$Z$56,'Child 2'!$Z$56,'Child 3'!$Z$56,'Child 4'!$Z$56),IF('Compare Calc'!$B$631=1,'Compare Calc'!$Z$665,"Not available"))) | D19: =IF(CHOOSE(CmpChild,'Child 1'!$B$22,'Child 2'!$B$22,'Child 3'!$B$22,'Child 4'!$B$22)<>1,"",IF(AND(NOT(CHOOSE(CmpChild,'Child 1'!$B$5,'Child 2'!$B$5,'Child 3'!$B$5,'Child 4'!$B$5)="United Arab Emirates"),'Compare Calc'!$B$631<>1),'Compare Calc'!$B$632,IF(IF(CHOOSE(CmpChild,'Child 1'!$B$5,'Child 2'!$B$5,'Child 3'!$B$5,'Child 4'!$B$5)="United Arab Emirates",CHOOSE(CmpChild,'Child 1'!$B$60,'Child 2'!$B$60,'Child 3'!$B$60,'Child 4'!$B$60),'Compare Calc'!$B$669)="estimated","Estimate — no published fee for this course",IF(IF(CHOOSE(CmpChild,'Child 1'!$B$5,'Child 2'!$B$5,'Child 3'!$B$5,'Child 4'!$B$5)="United Arab Emirates",CHOOSE(CmpChild,'Child 1'!$B$61,'Child 2'!$B$61,'Child 3'!$B$61,'Child 4'!$B$61),'Compare Calc'!$B$670)=1,"Some costs have no figure yet","")))) | E19: =IF(AND(CHOOSE(CmpChild,'Child 1'!$B$22,'Child 2'!$B$22,'Child 3'!$B$22,'Child 4'!$B$22)=1,CHOOSE(CmpChild,'Child 1'!$B$5,'Child 2'!$B$5,'Child 3'!$B$5,'Child 4'!$B$5)="United Arab Emirates"),"Current plan","")
B21: Each total covers the full course in that country (its usual length), at future prices, after your scholarship / part-time-work percentage. The current plan's row is your plan exactly. For other countries your own fee and living-cost increases are used, but your own cost figures are not carried over, because they are in another country's currency.

Sheet Child 1
A1: Child 1 - cost and savings calculation
A2: All formulas. Change inputs on the Inputs sheet. Amounts in the cost lines table are in the education country's currency; everything else is in the results currency.
A4: Included (1 = yes) | B4: =IF(1<=NumChildren,1,0) -> 1
A5: Education country | B5: =IF(Inputs!$C$17="","",Inputs!$C$17)
A6: Qualification | B6: =IF(Inputs!$C$18="","",Inputs!$C$18)
A7: Current age | B7: =IF(Inputs!$C$15="","",Inputs!$C$15)
A8: College-entry age | B8: =IF(Inputs!$C$19="","",Inputs!$C$19) -> 18
A9: Fee status | B9: =IF($B$5="","",IF(COUNTIF(DomKey,$B$5&"|"&Nationality)>0,"domestic","international"))
A10: Lookup key | B10: =$B$5&"|"&$B$6&"|"&$B$9 -> ||
A11: Cost database row | B11: =IFERROR(MATCH($B$10,DB_Key,0),0) -> 0
A12: Education currency | B12: =IFERROR(INDEX(Ctry_Ccy,MATCH($B$5,Ctry_Name,0)),"USD") -> USD
A13: Course length (years) | B13: =IF($B$11>0,INDEX(DB_Dur,$B$11),0) -> 0
A14: Offered in this country (1/0) | B14: =IF($B$11>0,INDEX(DB_Avail,$B$11),0) -> 0
A15: Pre-stage years | B15: =IF($B$11>0,INDEX(DB_PreYears,$B$11),0) -> 0
A16: Fee increase used | B16: =IF(ISNUMBER(Inputs!$C$20),Inputs!$C$20,IF($B$11>0,INDEX(DB_TInf,$B$11),0)) -> 0
A17: Living-cost increase used | B17: =IF(ISNUMBER(Inputs!$C$21),Inputs!$C$21,IFERROR(INDEX(Ctry_LInf,MATCH($B$5,Ctry_Name,0)),0)) -> 0
A18: Years until college | B18: =IF($B$22=1,MAX(0,$B$8-$B$7),0) -> 0
A19: Study years | B19: =ROUNDUP($B$13,0) -> 0
A20: Plan years | B20: =IF($B$22=1,$B$18+$B$19,0) -> 0
A21: Saving years | B21: =MAX(0,$B$20-1) -> 0
A22: Calculated (1 = yes) | B22: =IF(IFERROR(AND($B$4=1,$B$5<>"",$B$6<>"",$B$14=1,IFERROR(AND(ISNUMBER($B$7),$B$7>=0,$B$7<=18,INT($B$7)=$B$7),FALSE),IFERROR(AND(ISNUMBER($B$8),$B$8>=14,$B$8<=45,INT($B$8)=$B$8),FALSE)),FALSE),1,0) -> 0
A23: Message | B23: =IF($B$4<>1,"",IF(AND($B$7="",$B$5="",$B$6=""),"Enter this child's details on the Inputs sheet.",IF(NOT(IFERROR(AND(ISNUMBER($B$7),$B$7>=0,$B$7<=18,INT($B$7)=$B$7),FALSE)),"Choose the child's current age (0 to 18).",IF(NOT(IFERROR(AND(ISNUMBER($B$8),$B$8>=14,$B$8<=45,INT($B$8)=$B$8),FALSE)),"College-entry age must be a whole number from 14 to 45.",IF($B$5="","Choose the education country.",IF($B$6="","Choose the qualification.",IF($B$14<>1,"This qualification is not offered (or has no typical duration) in the selected country.",""))))))) -> Enter this child's details on the Inputs sheet.
A24: Exchange rate (education to results currency) | B24: =INDEX(FxUsed,MATCH(RepCcy,FxCodes,0))/INDEX(FxUsed,MATCH($B$12,FxCodes,0)) -> 1
A25: Published fee records used | B25: =IF($B$11=0,0,COUNTIF(RecKey,$B$10)) -> 0
A26: Fee records currency | B26: =IF($B$25>0,INDEX(DB_RecCcy,$B$11),IF($B$11>0,INDEX(DB_EstCcy,$B$11),$B$12)) -> USD
A27: Living costs row | B27: =IFERROR(MATCH($B$5&"|"&$B$9,LivKey,0),0) -> 0
A28: Visa row | B28: =IFERROR(MATCH($B$5&"|"&Nationality,VisaKey,0),0) -> 0
A29: Travel row | B29: =IFERROR(MATCH($B$5&"|"&Residence,TravKey,0),0) -> 0
A31: Cost line | B31: Researched (education currency) | C31: Your figure | D31: Amount used | E31: Price year | F31: Status code | G31: Status | H31: Increase | I31: Timing | J31: Scholarship applies
A32: Tuition | B32: =IF($B$11=0,0,(IF($B$25>0,SUMPRODUCT((RecKey=$B$10)*RecTuition*(1+$B$16)^(PlanYear-RecYear))/$B$25,INDEX(DB_EstTuition,$B$11)))/INDEX(FxUsed,MATCH($B$26,FxCodes,0))*INDEX(FxUsed,MATCH($B$12,FxCodes,0))) -> 0 | C32: =IF(ISNUMBER(Inputs!$C$23),Inputs!$C$23,"") | D32: =IF(ISNUMBER(C32),IF(C32>=0,C32,B32),B32) -> 0 | E32: =IF(ISNUMBER(C32),PlanYear,IF($B$25>0,PlanYear,IF($B$11>0,INDEX(DB_EstBase,$B$11),PlanYear))) -> 2026 | F32: =IF(ISNUMBER(C32),"override",IF($B$11=0,"missing",IF($B$25>0,"verified",INDEX(DB_EstStatus,$B$11)))) -> missing | G32: =IF(F32="verified","Published figure",IF(F32="estimated","Estimated — please review",IF(F32="notNeeded","Not needed",IF(F32="override","Your figure",IF(F32="missing","No figure yet — enter your own",""))))) -> No figure yet — enter your own | H32: tuition | I32: annual | J32: Yes
A33: Accommodation | B33: =IF($B$27=0,0,(INDEX(Liv_accommodation_Amt,$B$27))/INDEX(FxUsed,MATCH(INDEX(Liv_accommodation_Ccy,$B$27),FxCodes,0))*INDEX(FxUsed,MATCH($B$12,FxCodes,0))) -> 0 | C33: =IF(ISNUMBER(Inputs!$C$24),Inputs!$C$24,"") | D33: =IF(ISNUMBER(C33),IF(C33>=0,C33,B33),B33) -> 0 | E33: =IF(ISNUMBER(C33),PlanYear,IF($B$27=0,PlanYear,INDEX(Liv_accommodation_Base,$B$27))) -> 2026 | F33: =IF(ISNUMBER(C33),"override",IF($B$27=0,"missing",INDEX(Liv_accommodation_Status,$B$27))) -> missing | G33: =IF(F33="verified","Published figure",IF(F33="estimated","Estimated — please review",IF(F33="notNeeded","Not needed",IF(F33="override","Your figure",IF(F33="missing","No figure yet — enter your own",""))))) -> No figure yet — enter your own | H33: living | I33: annual | J33: Yes
A34: Food | B34: =IF($B$27=0,0,(INDEX(Liv_food_Amt,$B$27))/INDEX(FxUsed,MATCH(INDEX(Liv_food_Ccy,$B$27),FxCodes,0))*INDEX(FxUsed,MATCH($B$12,FxCodes,0))) -> 0 | C34: =IF(ISNUMBER(Inputs!$C$25),Inputs!$C$25,"") | D34: =IF(ISNUMBER(C34),IF(C34>=0,C34,B34),B34) -> 0 | E34: =IF(ISNUMBER(C34),PlanYear,IF($B$27=0,PlanYear,INDEX(Liv_food_Base,$B$27))) -> 2026 | F34: =IF(ISNUMBER(C34),"override",IF($B$27=0,"missing",INDEX(Liv_food_Status,$B$27))) -> missing | G34: =IF(F34="verified","Published figure",IF(F34="estimated","Estimated — please review",IF(F34="notNeeded","Not needed",IF(F34="override","Your figure",IF(F34="missing","No figure yet — enter your own",""))))) -> No figure yet — enter your own | H34: living | I34: annual | J34: Yes
A35: Local transport | B35: =IF($B$27=0,0,(INDEX(Liv_transport_Amt,$B$27))/INDEX(FxUsed,MATCH(INDEX(Liv_transport_Ccy,$B$27),FxCodes,0))*INDEX(FxUsed,MATCH($B$12,FxCodes,0))) -> 0 | C35: =IF(ISNUMBER(Inputs!$C$26),Inputs!$C$26,"") | D35: =IF(ISNUMBER(C35),IF(C35>=0,C35,B35),B35) -> 0 | E35: =IF(ISNUMBER(C35),PlanYear,IF($B$27=0,PlanYear,INDEX(Liv_transport_Base,$B$27))) -> 2026 | F35: =IF(ISNUMBER(C35),"override",IF($B$27=0,"missing",INDEX(Liv_transport_Status,$B$27))) -> missing | G35: =IF(F35="verified","Published figure",IF(F35="estimated","Estimated — please review",IF(F35="notNeeded","Not needed",IF(F35="override","Your figure",IF(F35="missing","No figure yet — enter your own",""))))) -> No figure yet — enter your own | H35: living | I35: annual | J35: Yes
A36: Health insurance | B36: =IF($B$27=0,0,(INDEX(Liv_healthInsurance_Amt,$B$27))/INDEX(FxUsed,MATCH(INDEX(Liv_healthInsurance_Ccy,$B$27),FxCodes,0))*INDEX(FxUsed,MATCH($B$12,FxCodes,0))) -> 0 | C36: =IF(ISNUMBER(Inputs!$C$27),Inputs!$C$27,"") | D36: =IF(ISNUMBER(C36),IF(C36>=0,C36,B36),B36) -> 0 | E36: =IF(ISNUMBER(C36),PlanYear,IF($B$27=0,PlanYear,INDEX(Liv_healthInsurance_Base,$B$27))) -> 2026 | F36: =IF(ISNUMBER(C36),"override",IF($B$27=0,"missing",INDEX(Liv_healthInsurance_Status,$B$27))) -> missing | G36: =IF(F36="verified","Published figure",IF(F36="estimated","Estimated — please review",IF(F36="notNeeded","Not needed",IF(F36="override","Your figure",IF(F36="missing","No figure yet — enter your own",""))))) -> No figure yet — enter your own | H36: living | I36: annual | J36: Yes
A37: Books and supplies | B37: =IF($B$27=0,0,(INDEX(Liv_books_Amt,$B$27))/INDEX(FxUsed,MATCH(INDEX(Liv_books_Ccy,$B$27),FxCodes,0))*INDEX(FxUsed,MATCH($B$12,FxCodes,0))) -> 0 | C37: =IF(ISNUMBER(Inputs!$C$28),Inputs!$C$28,"") | D37: =IF(ISNUMBER(C37),IF(C37>=0,C37,B37),B37) -> 0 | E37: =IF(ISNUMBER(C37),PlanYear,IF($B$27=0,PlanYear,INDEX(Liv_books_Base,$B$27))) -> 2026 | F37: =IF(ISNUMBER(C37),"override",IF($B$27=0,"missing",INDEX(Liv_books_Status,$B$27))) -> missing | G37: =IF(F37="verified","Published figure",IF(F37="estimated","Estimated — please review",IF(F37="notNeeded","Not needed",IF(F37="override","Your figure",IF(F37="missing","No figure yet — enter your own",""))))) -> No figure yet — enter your own | H37: living | I37: annual | J37: Yes
A38: Other university and course fees | B38: =IF($B$11=0,0,(IF($B$25>0,SUMPRODUCT((RecKey=$B$10)*RecOther*(1+$B$16)^(PlanYear-RecYear))/$B$25,INDEX(DB_EstOther,$B$11)))/INDEX(FxUsed,MATCH($B$26,FxCodes,0))*INDEX(FxUsed,MATCH($B$12,FxCodes,0))) -> 0 | C38: =IF(ISNUMBER(Inputs!$C$29),Inputs!$C$29,"") | D38: =IF(ISNUMBER(C38),IF(C38>=0,C38,B38),B38) -> 0 | E38: =IF(ISNUMBER(C38),PlanYear,IF($B$25>0,PlanYear,IF($B$11>0,INDEX(DB_EstBase,$B$11),PlanYear))) -> 2026 | F38: =IF(ISNUMBER(C38),"override",IF($B$11=0,"missing",IF($B$25>0,"verified",INDEX(DB_EstStatus,$B$11)))) -> missing | G38: =IF(F38="verified","Published figure",IF(F38="estimated","Estimated — please review",IF(F38="notNeeded","Not needed",IF(F38="override","Your figure",IF(F38="missing","No figure yet — enter your own",""))))) -> No figure yet — enter your own | H38: tuition | I38: annual | J38: Yes
A39: Admission and one-time fees | B39: =IF($B$15>0,IF($B$15>0,(INDEX(DB_PreAdm,$B$11))/INDEX(FxUsed,MATCH(INDEX(DB_PreCcy,$B$11),FxCodes,0))*INDEX(FxUsed,MATCH($B$12,FxCodes,0)),0),IF($B$11=0,0,(IF($B$25>0,SUMPRODUCT((RecKey=$B$10)*RecAdm*(1+$B$16)^(PlanYear-RecYear))/$B$25,INDEX(DB_EstAdm,$B$11)))/INDEX(FxUsed,MATCH($B$26,FxCodes,0))*INDEX(FxUsed,MATCH($B$12,FxCodes,0)))) -> 0 | C39: =IF(ISNUMBER(Inputs!$C$30),Inputs!$C$30,"") | D39: =IF(ISNUMBER(C39),IF(C39>=0,C39,B39),B39) -> 0 | E39: =IF(ISNUMBER(C39),PlanYear,IF($B$15>0,INDEX(DB_PreBase,$B$11),IF($B$25>0,PlanYear,IF($B$11>0,INDEX(DB_EstBase,$B$11),PlanYear)))) -> 2026 | F39: =IF(ISNUMBER(C39),"override",IF($B$15>0,INDEX(DB_PreStatus,$B$11),IF($B$11=0,"missing",IF($B$25>0,"verified",INDEX(DB_EstStatus,$B$11))))) -> missing | G39: =IF(F39="verified","Published figure",IF(F39="estimated","Estimated — please review",IF(F39="notNeeded","Not needed",IF(F39="override","Your figure",IF(F39="missing","No figure yet — enter your own",""))))) -> No figure yet — enter your own | H39: tuition | I39: once | J39: Yes
A40: Visa and application | B40: =IF(OR($B$28=0,AND($B$9<>"domestic",Residence=$B$5,COUNTIF(ResNoVisa,$B$5)>0)),0,(INDEX(VisaAmt,$B$28))/INDEX(FxUsed,MATCH(INDEX(VisaCcy,$B$28),FxCodes,0))*INDEX(FxUsed,MATCH($B$12,FxCodes,0))) -> 0 | C40: =IF(ISNUMBER(Inputs!$C$31),Inputs!$C$31,"") | D40: =IF(ISNUMBER(C40),IF(C40>=0,C40,B40),B40) -> 0 | E40: =IF(ISNUMBER(C40),PlanYear,IF(OR($B$28=0,AND($B$9<>"domestic",Residence=$B$5,COUNTIF(ResNoVisa,$B$5)>0)),PlanYear,INDEX(VisaBase,$B$28))) -> 2026 | F40: =IF(ISNUMBER(C40),"override",IF(AND($B$9<>"domestic",Residence=$B$5,COUNTIF(ResNoVisa,$B$5)>0),"notNeeded",IF($B$28=0,"missing",INDEX(VisaStatus,$B$28)))) -> missing | G40: =IF(F40="verified","Published figure",IF(F40="estimated","Estimated — please review",IF(F40="notNeeded","Not needed",IF(F40="override","Your figure",IF(F40="missing","No figure yet — enter your own",""))))) -> No figure yet — enter your own | H40: living | I40: once | J40: No
A41: Travel and relocation | B41: =IF($B$29=0,0,(INDEX(TravAmt,$B$29))/INDEX(FxUsed,MATCH(INDEX(TravCcy,$B$29),FxCodes,0))*INDEX(FxUsed,MATCH($B$12,FxCodes,0))) -> 0 | C41: =IF(ISNUMBER(Inputs!$C$32),Inputs!$C$32,"") | D41: =IF(ISNUMBER(C41),IF(C41>=0,C41,B41),B41) -> 0 | E41: =IF(ISNUMBER(C41),PlanYear,IF($B$29=0,PlanYear,INDEX(TravBase,$B$29))) -> 2026 | F41: =IF(ISNUMBER(C41),"override",IF($B$29=0,"missing",INDEX(TravStatus,$B$29))) -> missing | G41: =IF(F41="verified","Published figure",IF(F41="estimated","Estimated — please review",IF(F41="notNeeded","Not needed",IF(F41="override","Your figure",IF(F41="missing","No figure yet — enter your own",""))))) -> No figure yet — enter your own | H41: living | I41: once | J41: No
A42: Pre-stage tuition (e.g. pre-medical degree) | B42: =IF($B$15>0,(INDEX(DB_PreTuition,$B$11))/INDEX(FxUsed,MATCH(INDEX(DB_PreCcy,$B$11),FxCodes,0))*INDEX(FxUsed,MATCH($B$12,FxCodes,0)),0) -> 0 | C42: =IF(ISNUMBER(Inputs!$C$33),Inputs!$C$33,"") | D42: =IF(ISNUMBER(C42),IF(C42>=0,C42,B42),B42) -> 0 | E42: =IF(ISNUMBER(C42),PlanYear,IF($B$15>0,INDEX(DB_PreBase,$B$11),PlanYear)) -> 2026 | F42: =IF(ISNUMBER(C42),"override",IF($B$15>0,INDEX(DB_PreStatus,$B$11),"")) | G42: =IF(F42="verified","Published figure",IF(F42="estimated","Estimated — please review",IF(F42="notNeeded","Not needed",IF(F42="override","Your figure",IF(F42="missing","No figure yet — enter your own",""))))) | H42: tuition | I42: annual | J42: Yes
...

Sheet Child 2
A1: Child 2 - cost and savings calculation
A2: All formulas. Change inputs on the Inputs sheet. Amounts in the cost lines table are in the education country's currency; everything else is in the results currency.
A4: Included (1 = yes) | B4: =IF(2<=NumChildren,1,0) -> 0
A5: Education country | B5: =IF(Inputs!$D$17="","",Inputs!$D$17)
A6: Qualification | B6: =IF(Inputs!$D$18="","",Inputs!$D$18)
A7: Current age | B7: =IF(Inputs!$D$15="","",Inputs!$D$15)
A8: College-entry age | B8: =IF(Inputs!$D$19="","",Inputs!$D$19) -> 18
A9: Fee status | B9: =IF($B$5="","",IF(COUNTIF(DomKey,$B$5&"|"&Nationality)>0,"domestic","international"))
A10: Lookup key | B10: =$B$5&"|"&$B$6&"|"&$B$9 -> ||
A11: Cost database row | B11: =IFERROR(MATCH($B$10,DB_Key,0),0) -> 0
A12: Education currency | B12: =IFERROR(INDEX(Ctry_Ccy,MATCH($B$5,Ctry_Name,0)),"USD") -> USD
A13: Course length (years) | B13: =IF($B$11>0,INDEX(DB_Dur,$B$11),0) -> 0
A14: Offered in this country (1/0) | B14: =IF($B$11>0,INDEX(DB_Avail,$B$11),0) -> 0
A15: Pre-stage years | B15: =IF($B$11>0,INDEX(DB_PreYears,$B$11),0) -> 0
A16: Fee increase used | B16: =IF(ISNUMBER(Inputs!$D$20),Inputs!$D$20,IF($B$11>0,INDEX(DB_TInf,$B$11),0)) -> 0
A17: Living-cost increase used | B17: =IF(ISNUMBER(Inputs!$D$21),Inputs!$D$21,IFERROR(INDEX(Ctry_LInf,MATCH($B$5,Ctry_Name,0)),0)) -> 0
A18: Years until college | B18: =IF($B$22=1,MAX(0,$B$8-$B$7),0) -> 0
A19: Study years | B19: =ROUNDUP($B$13,0) -> 0
A20: Plan years | B20: =IF($B$22=1,$B$18+$B$19,0) -> 0
A21: Saving years | B21: =MAX(0,$B$20-1) -> 0
A22: Calculated (1 = yes) | B22: =IF(IFERROR(AND($B$4=1,$B$5<>"",$B$6<>"",$B$14=1,IFERROR(AND(ISNUMBER($B$7),$B$7>=0,$B$7<=18,INT($B$7)=$B$7),FALSE),IFERROR(AND(ISNUMBER($B$8),$B$8>=14,$B$8<=45,INT($B$8)=$B$8),FALSE)),FALSE),1,0) -> 0
A23: Message | B23: =IF($B$4<>1,"",IF(AND($B$7="",$B$5="",$B$6=""),"Enter this child's details on the Inputs sheet.",IF(NOT(IFERROR(AND(ISNUMBER($B$7),$B$7>=0,$B$7<=18,INT($B$7)=$B$7),FALSE)),"Choose the child's current age (0 to 18).",IF(NOT(IFERROR(AND(ISNUMBER($B$8),$B$8>=14,$B$8<=45,INT($B$8)=$B$8),FALSE)),"College-entry age must be a whole number from 14 to 45.",IF($B$5="","Choose the education country.",IF($B$6="","Choose the qualification.",IF($B$14<>1,"This qualification is not offered (or has no typical duration) in the selected country.","")))))))
A24: Exchange rate (education to results currency) | B24: =INDEX(FxUsed,MATCH(RepCcy,FxCodes,0))/INDEX(FxUsed,MATCH($B$12,FxCodes,0)) -> 1
A25: Published fee records used | B25: =IF($B$11=0,0,COUNTIF(RecKey,$B$10)) -> 0
A26: Fee records currency | B26: =IF($B$25>0,INDEX(DB_RecCcy,$B$11),IF($B$11>0,INDEX(DB_EstCcy,$B$11),$B$12)) -> USD
A27: Living costs row | B27: =IFERROR(MATCH($B$5&"|"&$B$9,LivKey,0),0) -> 0
A28: Visa row | B28: =IFERROR(MATCH($B$5&"|"&Nationality,VisaKey,0),0) -> 0
A29: Travel row | B29: =IFERROR(MATCH($B$5&"|"&Residence,TravKey,0),0) -> 0
A31: Cost line | B31: Researched (education currency) | C31: Your figure | D31: Amount used | E31: Price year | F31: Status code | G31: Status | H31: Increase | I31: Timing | J31: Scholarship applies
A32: Tuition | B32: =IF($B$11=0,0,(IF($B$25>0,SUMPRODUCT((RecKey=$B$10)*RecTuition*(1+$B$16)^(PlanYear-RecYear))/$B$25,INDEX(DB_EstTuition,$B$11)))/INDEX(FxUsed,MATCH($B$26,FxCodes,0))*INDEX(FxUsed,MATCH($B$12,FxCodes,0))) -> 0 | C32: =IF(ISNUMBER(Inputs!$D$23),Inputs!$D$23,"") | D32: =IF(ISNUMBER(C32),IF(C32>=0,C32,B32),B32) -> 0 | E32: =IF(ISNUMBER(C32),PlanYear,IF($B$25>0,PlanYear,IF($B$11>0,INDEX(DB_EstBase,$B$11),PlanYear))) -> 2026 | F32: =IF(ISNUMBER(C32),"override",IF($B$11=0,"missing",IF($B$25>0,"verified",INDEX(DB_EstStatus,$B$11)))) -> missing | G32: =IF(F32="verified","Published figure",IF(F32="estimated","Estimated — please review",IF(F32="notNeeded","Not needed",IF(F32="override","Your figure",IF(F32="missing","No figure yet — enter your own",""))))) -> No figure yet — enter your own | H32: tuition | I32: annual | J32: Yes
A33: Accommodation | B33: =IF($B$27=0,0,(INDEX(Liv_accommodation_Amt,$B$27))/INDEX(FxUsed,MATCH(INDEX(Liv_accommodation_Ccy,$B$27),FxCodes,0))*INDEX(FxUsed,MATCH($B$12,FxCodes,0))) -> 0 | C33: =IF(ISNUMBER(Inputs!$D$24),Inputs!$D$24,"") | D33: =IF(ISNUMBER(C33),IF(C33>=0,C33,B33),B33) -> 0 | E33: =IF(ISNUMBER(C33),PlanYear,IF($B$27=0,PlanYear,INDEX(Liv_accommodation_Base,$B$27))) -> 2026 | F33: =IF(ISNUMBER(C33),"override",IF($B$27=0,"missing",INDEX(Liv_accommodation_Status,$B$27))) -> missing | G33: =IF(F33="verified","Published figure",IF(F33="estimated","Estimated — please review",IF(F33="notNeeded","Not needed",IF(F33="override","Your figure",IF(F33="missing","No figure yet — enter your own",""))))) -> No figure yet — enter your own | H33: living | I33: annual | J33: Yes
A34: Food | B34: =IF($B$27=0,0,(INDEX(Liv_food_Amt,$B$27))/INDEX(FxUsed,MATCH(INDEX(Liv_food_Ccy,$B$27),FxCodes,0))*INDEX(FxUsed,MATCH($B$12,FxCodes,0))) -> 0 | C34: =IF(ISNUMBER(Inputs!$D$25),Inputs!$D$25,"") | D34: =IF(ISNUMBER(C34),IF(C34>=0,C34,B34),B34) -> 0 | E34: =IF(ISNUMBER(C34),PlanYear,IF($B$27=0,PlanYear,INDEX(Liv_food_Base,$B$27))) -> 2026 | F34: =IF(ISNUMBER(C34),"override",IF($B$27=0,"missing",INDEX(Liv_food_Status,$B$27))) -> missing | G34: =IF(F34="verified","Published figure",IF(F34="estimated","Estimated — please review",IF(F34="notNeeded","Not needed",IF(F34="override","Your figure",IF(F34="missing","No figure yet — enter your own",""))))) -> No figure yet — enter your own | H34: living | I34: annual | J34: Yes
